Workbook
Name ActiveScenario: "'Scenario Engine'!B3"
Name BaseWACC: "'Sensitivity Analysis'!B5"
Name IntrinsicValue: "'WACC & DCF Valuation'!B81"
Name SharesOutstanding: "'WACC & DCF Valuation'!B80"
Name TerminalGrowth: "'WACC & DCF Valuation'!B56"
Name WACC: "'WACC & DCF Valuation'!B32"

Sheet Navigation
B2: Jindal Coke Ltd. — Financial Model Navigation Index
B3: Model Version: EXP v2.0 | Last Updated: Apr 2026 | Prepared by: Divyanshu Vatsa
B5: # | C5: Sheet Name | D5: Purpose | E5: Key Outputs
B6: 1 | C6: Model Checks | D6: Automated integrity validation | E6: 47+ PASS/FAIL tests (BS balance, cash, debt, dep)
B7: 2 | C7: Scenario Engine | D7: Bull / Base / Bear assumption toggle | E7: Active scenario drives all projections & DCF
B8: 3 | C8: Dashboard | D8: Executive summary with charts | E8: Key metrics, valuation, covenant tracker, thesis
B9: 4 | C9: Historical FS | D9: 10-year cleaned financials (FY16–FY25) | E9: P&L, BS, CF with formula references
B10: 5 | C10: Ratio Analysis | D10: 35+ ratios with interpretations | E10: Growth, profitability, leverage, efficiency
B11: 6 | C11: Common Size Statements | D11: Percentage-of-total analysis | E11: Structural composition trends
B12: 7 | C12: Assumptions & Drivers | D12: All projection inputs & cost drivers | E12: Revenue, COGS decomposition, WC, capex, debt, tax
B13: 8 | C13: The 3-Statement Projection | D13: Integrated P&L, BS, CF (FY25A–FY33E) | E13: Core financial outputs + balance checks
B14: 9 | C14: WACC & DCF Valuation | D14: DCF model with WACC build | E14: ="Intrinsic value per share (₹"&TEXT('WACC & DCF Valuation'!B81,"0")&")" -> Intrinsic value per share (₹515)
B15: 10 | C15: Sensitivity Analysis | D15: 2-way WACC × Terminal g table | E15: ="Valuation range ₹"&TEXT(MIN('Sensitivity Analysis'!B11:F15),"#,##0")&"–₹"&TEXT(MAX('Sensitivity Analysis'!B11:F15),"#,##0") -> Valuation range ₹466–₹747
B16: 11 | C16: Comparable Company Analysis | D16: EV/EBITDA comps (Sandur Manganese) | E16: Blended valuation cross-check
B17: 12 | C17: Production & Offtake | D17: Bottom-up volume × price build | E17: Revenue reconciliation to mentor benchmark
B18: 13 | C18: Depreciation Schedule | D18: Book SL + IT WDV by asset class | E18: Feeds P&L depreciation and Tax Working
B19: 14 | C19: Tax Working | D19: CIT vs MAT dual test | E19: Tax expense + DTL movement
B20: 15 | C20: Debt Schedule | D20: TL + BC + WC + Revolver roll-forward | E20: Interest expense + debt balances
B21: 16 | C21: Working Capital Schedule | D21: Tandon-style MPBF calculation | E21: WC gap + bank finance limit
B22: 17 | C22: DSCR Covenant Tracker | D22: Lender covenant compliance | E22: DSCR, ISCR, FACR status checks
B24: COLOR CODING LEGEND
B25: ■ Blue Text = Hardcoded Assumption (Editable Input)
B26: ■ Black Text = Formula / Derived Calculation (Do Not Edit)
B27: ■ Green Text = Cross-Sheet Link (References another tab)
B28: ■ Red Text = External Link (References another workbook)
B29: ■ Yellow Background = Key Assumption Needing Attention

Sheet Model Checks
B1: Jindal Coke Ltd. — Model Integrity Checks
B2: Automated PASS / FAIL tests. Red = requires attention.
A4: # | B4: Check Description | C4: Status | D4: Detail / Formula
B5: 1. BALANCE SHEET CHECKS
A6: 1 | B6: BS Balance: Total Assets = Total E+L (FY24A) | C6: =IF(ABS('The 3-Statement Projection'!B105)<0.05,"PASS","FAIL") -> PASS | D6: ='The 3-Statement Projection'!B105 -> 0
A7: 2 | B7: BS Balance: Total Assets = Total E+L (FY25A) | C7: =IF(ABS('The 3-Statement Projection'!C105)<0.05,"PASS","FAIL") -> PASS | D7: ='The 3-Statement Projection'!C105 -> 0
A8: 3 | B8: BS Balance: Total Assets = Total E+L (FY26E) | C8: =IF(ABS('The 3-Statement Projection'!D105)<0.05,"PASS","FAIL") -> PASS | D8: ='The 3-Statement Projection'!D105 -> 0
A9: 4 | B9: BS Balance: Total Assets = Total E+L (FY27E) | C9: =IF(ABS('The 3-Statement Projection'!E105)<0.05,"PASS","FAIL") -> PASS | D9: ='The 3-Statement Projection'!E105 -> 0
A10: 5 | B10: BS Balance: Total Assets = Total E+L (FY28E) | C10: =IF(ABS('The 3-Statement Projection'!F105)<0.05,"PASS","FAIL") -> PASS | D10: ='The 3-Statement Projection'!F105 -> 0
A11: 6 | B11: BS Balance: Total Assets = Total E+L (FY29E) | C11: =IF(ABS('The 3-Statement Projection'!G105)<0.05,"PASS","FAIL") -> PASS | D11: ='The 3-Statement Projection'!G105 -> 0
A12: 7 | B12: BS Balance: Historical FS FY25A (Assets - E+L) | C12: =IF(ABS('Historical FS'!L96-'Historical FS'!L74)<0.1,"PASS","FAIL") -> PASS | D12: ='Historical FS'!L96-'Historical FS'!L74 -> 0
B14: 2. CASH FLOW CHECKS
A15: 10 | B15: Historical CF: Closing Cash = BS Cash (FY25A) | C15: =IF(ABS('Historical FS'!L141-'Historical FS'!L91)<0.1,"PASS","FAIL") -> PASS | D15: ='Historical FS'!L141-'Historical FS'!L91 -> 0
A16: 11 | B16: 3-Stmt CF: Closing Cash = BS Cash (FY26E) | C16: =IF(ABS('The 3-Statement Projection'!D102-'The 3-Statement Projection'!D67)<0.05,"PASS","FAIL") -> PASS | D16: ='The 3-Statement Projection'!D102-'The 3-Statement Projection'!D67 -> 0
A17: 12 | B17: 3-Stmt CF: Closing Cash = BS Cash (FY27E) | C17: =IF(ABS('The 3-Statement Projection'!E102-'The 3-Statement Projection'!E67)<0.05,"PASS","FAIL") -> PASS | D17: ='The 3-Statement Projection'!E102-'The 3-Statement Projection'!E67 -> 0
A18: 13 | B18: 3-Stmt CF: Closing Cash = BS Cash (FY28E) | C18: =IF(ABS('The 3-Statement Projection'!F102-'The 3-Statement Projection'!F67)<0.05,"PASS","FAIL") -> PASS | D18: ='The 3-Statement Projection'!F102-'The 3-Statement Projection'!F67 -> 0
A19: 14 | B19: 3-Stmt CF: Closing Cash = BS Cash (FY29E) | C19: =IF(ABS('The 3-Statement Projection'!G102-'The 3-Statement Projection'!G67)<0.05,"PASS","FAIL") -> PASS | D19: ='The 3-Statement Projection'!G102-'The 3-Statement Projection'!G67 -> 0
B21: 3. DEBT SCHEDULE CHECKS
A22: 17 | B22: Debt Roll-Forward: TL Opening + Draw = Closing (FY25A) | C22: =IF(ABS('The 3-Statement Projection'!C109)<0.05,"PASS","FAIL") -> PASS | D22: ='The 3-Statement Projection'!C109 -> 0
A23: 18 | B23: Debt Roll-Forward: TL Opening + Draw = Closing (FY26E) | C23: =IF(ABS('The 3-Statement Projection'!D109)<0.05,"PASS","FAIL") -> PASS | D23: ='The 3-Statement Projection'!D109 -> 0
A24: 19 | B24: Debt Roll-Forward: TL Opening + Draw = Closing (FY27E) | C24: =IF(ABS('The 3-Statement Projection'!E109)<0.05,"PASS","FAIL") -> PASS | D24: ='The 3-Statement Projection'!E109 -> 0
A25: 20 | B25: Debt Roll-Forward: TL Opening + Draw = Closing (FY28E) | C25: =IF(ABS('The 3-Statement Projection'!F109)<0.05,"PASS","FAIL") -> PASS | D25: ='The 3-Statement Projection'!F109 -> 0
A26: 21 | B26: Debt Roll-Forward: TL Opening + Draw = Closing (FY29E) | C26: =IF(ABS('The 3-Statement Projection'!G109)<0.05,"PASS","FAIL") -> PASS | D26: ='The 3-Statement Projection'!G109 -> 0
A27: 22 | B27: Revolver Roll-Forward (FY26E) | C27: =IF(ABS('The 3-Statement Projection'!D110)<0.05,"PASS","FAIL") -> PASS | D27: ='The 3-Statement Projection'!D110 -> 0
A28: 23 | B28: Revolver Roll-Forward (FY27E) | C28: =IF(ABS('The 3-Statement Projection'!E110)<0.05,"PASS","FAIL") -> PASS | D28: ='The 3-Statement Projection'!E110 -> 0
A29: 24 | B29: Revolver Roll-Forward (FY28E) | C29: =IF(ABS('The 3-Statement Projection'!F110)<0.05,"PASS","FAIL") -> PASS | D29: ='The 3-Statement Projection'!F110 -> 0
A30: 25 | B30: Revolver Roll-Forward (FY29E) | C30: =IF(ABS('The 3-Statement Projection'!G110)<0.05,"PASS","FAIL") -> PASS | D30: ='The 3-Statement Projection'!G110 -> 0
B32: 4. DEPRECIATION LINKAGE
A33: 28 | B33: Depreciation: Schedule = 3-Stmt P&L (FY26E) | C33: =IF(ABS('Depreciation Schedule'!E21-'The 3-Statement Projection'!D18)<0.05,"PASS","FAIL") -> PASS | D33: ='Depreciation Schedule'!E21-'The 3-Statement Projection'!D18 -> 0
A34: 29 | B34: Depreciation: Schedule = 3-Stmt P&L (FY27E) | C34: =IF(ABS('Depreciation Schedule'!F21-'The 3-Statement Projection'!E18)<0.05,"PASS","FAIL") -> PASS | D34: ='Depreciation Schedule'!F21-'The 3-Statement Projection'!E18 -> 0
A35: 30 | B35: Depreciation: Schedule = 3-Stmt P&L (FY28E) | C35: =IF(ABS('Depreciation Schedule'!G21-'The 3-Statement Projection'!F18)<0.05,"PASS","FAIL") -> PASS | D35: ='Depreciation Schedule'!G21-'The 3-Statement Projection'!F18 -> 0
A36: 31 | B36: Depreciation: Schedule = 3-Stmt P&L (FY29E) | C36: =IF(ABS('Depreciation Schedule'!H21-'The 3-Statement Projection'!G18)<0.05,"PASS","FAIL") -> PASS | D36: ='Depreciation Schedule'!H21-'The 3-Statement Projection'!G18 -> 0
B38: 5. REVENUE CONSISTENCY
A39: 34 | B39: Revenue: Dashboard = 3-Stmt (FY25A) | C39: =IF(ABS(Dashboard!D6-'The 3-Statement Projection'!C6)<0.01,"PASS","FAIL") -> PASS | D39: =Dashboard!D6-'The 3-Statement Projection'!C6 -> 0
A40: 35 | B40: Revenue: Dashboard = 3-Stmt (FY26E) | C40: =IF(ABS(Dashboard!E6-'The 3-Statement Projection'!D6)<0.01,"PASS","FAIL") -> PASS | D40: =Dashboard!E6-'The 3-Statement Projection'!D6 -> 0
A41: 36 | B41: Revenue: Dashboard = 3-Stmt (FY27E) | C41: =IF(ABS(Dashboard!F6-'The 3-Statement Projection'!E6)<0.01,"PASS","FAIL") -> PASS | D41: =Dashboard!F6-'The 3-Statement Projection'!E6 -> 0
A42: 37 | B42: Revenue: Dashboard = 3-Stmt (FY28E) | C42: =IF(ABS(Dashboard!G6-'The 3-Statement Projection'!F6)<0.01,"PASS","FAIL") -> PASS | D42: =Dashboard!G6-'The 3-Statement Projection'!F6 -> 0
A43: 38 | B43: Revenue: Dashboard = 3-Stmt (FY29E) | C43: =IF(ABS(Dashboard!H6-'The 3-Statement Projection'!G6)<0.01,"PASS","FAIL") -> PASS | D43: =Dashboard!H6-'The 3-Statement Projection'!G6 -> 0
B45: 6. INTEREST EXPENSE LINKAGE
A46: 41 | B46: Interest: Debt Schedule = 3-Stmt (FY26E) | C46: =IF(ABS('Debt Schedule'!E25-'The 3-Statement Projection'!D21)<0.05,"PASS","FAIL") -> PASS | D46: ='Debt Schedule'!E25-'The 3-Statement Projection'!D21 -> 0
...

Sheet Scenario Engine
A1: Scenario Engine
A2: Select a scenario below. All projection sheets, DCF, and Dashboard cascade automatically.
A3: Active Scenario: | B3: Base | C3: ← Change this cell (dropdown)
A5: 1. COST & PROFITABILITY DRIVERS
A6: Driver | B6: Bull | C6: Base | D6: Bear | E6: Rationale
A7: COGS (% of Net Sales) | B7: 0.79 | C7: 0.82 | D7: 0.85 | E7: Bull: favorable coal spreads; Bear: input cost squeeze
A8: Employee Benefit Exp (% Sales) | B8: 0.0088 | C8: 0.0093 | D8: 0.01 | E8: Operating leverage on employee costs
A9: SG&A Expenses (% Sales) | B9: 0.035 | C9: 0.0374 | D9: 0.04 | E9: Fixed cost dilution at scale vs. cost inflation
A10: Assumed USD/INR Rate | B10: 82 | C10: 85 | D10: 91 | E10: Bull: strong INR; Bear: 5-7% depreciation from base
A11: Coking Coal (USD/MT) | B11: 150 | C11: 170 | D11: 210 | E11: Bull: low coal cost ($150); Base: mid-cycle ($170); Bear: squeeze ($210/MT)
A12: Consumption Ratio (MT coal / MT coke) | B12: 1.4 | C12: 1.4 | D12: 1.4 | E12: Industry standard: ~1.35-1.45x yield loss in coke conversion
A13: Domestic Processing Cost (₹/MT) | B13: 8000 | C13: 8470 | D13: 9000 | E13: Bull: efficient ops (₹8,000/MT); Base: ₹8,470/MT; Bear: cost inflation (₹9,000/MT)
A14: Domestic Cost Inflation (%) | B14: 0.02 | C14: 0.03243 | D14: 0.04 | E14: Annual escalation on domestic conversion, power, freight costs
A16: 2. WORKING CAPITAL DRIVERS
A17: Driver | B17: Bull | C17: Base | D17: Bear | E17: Rationale
A18: Debtor Days | B18: 30 | C18: 35 | D18: 45 | E18: Bull: JSL group collections faster; Bear: delayed payments
A19: Inventory Days | B19: 40 | C19: 45 | D19: 55 | E19: Bear: coal supply chain disruptions, longer buffer needed
A20: Payable Days | B20: 45 | C20: 40 | D20: 35 | E20: Bull: better supplier terms; Bear: tighter credit
A22: 3. CAPEX & DEPRECIATION
A23: Driver | B23: Bull | C23: Base | D23: Bear | E23: Rationale
A25: 4. FINANCING DRIVERS
A26: Driver | B26: Bull | C26: Base | D26: Bear | E26: Rationale
A27: Interest Rate on Debt (%) | B27: 0.085 | C27: 0.09 | D27: 0.1 | E27: Bull: rate easing (RBI cuts); Bear: tighter credit
A29: 5. DCF / WACC ASSUMPTIONS
A30: Driver | B30: Bull | C30: Base | D30: Bear | E30: Rationale
A31: Terminal Growth Rate (g) | B31: 0.02 | C31: 0 | D31: 0 | E31: Bull: secular India growth; Bear: global steel downcycle
A32: Unlevered Beta (βu) | B32: 0.8 | C32: 0.85 | D32: 0.95 | E32: Bear: higher systematic risk in downcycle
A33: Pre-tax Cost of Debt | B33: =B27 -> 0.085 | C33: =C27 -> 0.09 | D33: =D27 -> 0.1 | E33: Same as financing driver above — flows to WACC
A35: LIVE OUTPUT (cascaded from active scenario)
A36: WACC | B36: ='WACC & DCF Valuation'!B32 -> 0.12514351 | C36: Implied EV (₹ Cr) | D36: ='WACC & DCF Valuation'!B65 -> 2114.246
A37: Terminal g | B37: ='WACC & DCF Valuation'!B56 -> 0 | C37: Equity Value (₹ Cr) | D37: ='WACC & DCF Valuation'!B76 -> 1669.346
A38: Net Sales FY25A | B38: ='Assumptions & Drivers'!D10 -> 1680.3612 | C38: Intrinsic Value / Share (₹) | D38: ='WACC & DCF Valuation'!B81 -> 514.75362
A40: 7. MENTOR-ALIGNED DRIVERS (added Nov 2025)
A41: Driver | B41: Bull | C41: Base | D41: Bear | E41: Rationale
A42: COB-1 Installed Capacity (MT) | B42: 429000 | C42: 429000 | D42: 429000 | E42: Fixed existing battery capacity (0.429 MTPA)
A43: COB-2 Installed Capacity (MT) | B43: 350000 | C43: 350000 | D43: 350000
A44: COB-1 Utilization % (flat) | B44: 0.92 | C44: 0.911766 | D44: 0.85
A45: COB-2 Util FY25A | B45: 0.5 | C45: 0.35 | D45: 0.25 | E45: New battery commissioning ramp-up
A46: COB-2 Util FY26E | B46: 0.8 | C46: 0.7 | D46: 0.55
A47: COB-2 Util FY27E | B47: 0.85 | C47: 0.8 | D47: 0.7
...

Sheet Dashboard
B1: ="Jindal Coke Ltd. — Executive Dashboard | Model v2.0 | Scenario: "&'Scenario Engine'!B3&" | "&TEXT(TODAY(),"dd-mmm-yyyy") -> Jindal Coke Ltd. — Executive Dashboard | Model v2.0 | Scenario: Base | 29-May-2026
B2: All figures in ₹ Crores unless stated otherwise | FY ends March 31
B4: 1. KEY FINANCIAL SUMMARY
B5: Metric | C5: FY24A | D5: FY25A | E5: FY26E | F5: FY27E | G5: FY28E | H5: FY29E | I5: FY30E | J5: FY31E | K5: FY32E | L5: FY33E
B6: Net Sales (₹ Cr) | C6: ='The 3-Statement Projection'!B6 -> 1572.8 | D6: ='The 3-Statement Projection'!C6 -> 1871.33 | E6: ='The 3-Statement Projection'!D6 -> 2081.1111 | F6: ='The 3-Statement Projection'!E6 -> 2195.6111 | G6: ='The 3-Statement Projection'!F6 -> 2195.6111 | H6: ='The 3-Statement Projection'!G6 -> 2195.6111 | I6: ='The 3-Statement Projection'!H6 -> 2195.6111 | J6: ='The 3-Statement Projection'!I6 -> 2195.6111 | ... L6: ='The 3-Statement Projection'!K6 -> 2195.6111
B7: EBITDA Margin (%) | C7: ='The 3-Statement Projection'!B16 -> 0.10350966 | D7: ='The 3-Statement Projection'!C16 -> 0.10711099 | E7: ='The 3-Statement Projection'!D16 -> 0.18247245 | F7: ='The 3-Statement Projection'!E16 -> 0.16406871 | G7: ='The 3-Statement Projection'!F16 -> 0.16606871 | H7: ='The 3-Statement Projection'!G16 -> 0.16806871 | I7: ='The 3-Statement Projection'!H16 -> 0.16806871 | J7: ='The 3-Statement Projection'!I16 -> 0.16806871 | ... L7: ='The 3-Statement Projection'!K16 -> 0.16806871
B8: Net Profit (₹ Cr) | C8: ='The 3-Statement Projection'!B27 -> 95.89 | D8: ='The 3-Statement Projection'!C27 -> 114.6 | E8: ='The 3-Statement Projection'!D27 -> 225.81068 | F8: ='The 3-Statement Projection'!E27 -> 199.77612 | G8: ='The 3-Statement Projection'!F27 -> 210.34615 | H8: ='The 3-Statement Projection'!G27 -> 215.82119 | I8: ='The 3-Statement Projection'!H27 -> 217.875 | J8: ='The 3-Statement Projection'!I27 -> 219.89403 | ... L8: ='The 3-Statement Projection'!K27 -> 223.85558
B9: Total Debt (₹ Cr) | C9: ='The 3-Statement Projection'!B39+'The 3-Statement Projection'!B45+'The 3-Statement Projection'!B46 -> 324.82 | D9: ='The 3-Statement Projection'!C39+'The 3-Statement Projection'!C45+'The 3-Statement Projection'!C46 -> 545.82 | E9: ='The 3-Statement Projection'!D39+'The 3-Statement Projection'!D45+'The 3-Statement Projection'!D46 -> 613.1 | F9: ='The 3-Statement Projection'!E39+'The 3-Statement Projection'!E45+'The 3-Statement Projection'!E46 -> 419.11871 | G9: ='The 3-Statement Projection'!F39+'The 3-Statement Projection'!F45+'The 3-Statement Projection'!F46 -> 351.8 | H9: ='The 3-Statement Projection'!G39+'The 3-Statement Projection'!G45+'The 3-Statement Projection'!G46 -> 306.5 | I9: ='The 3-Statement Projection'!H39+'The 3-Statement Projection'!H45+'The 3-Statement Projection'!H46 -> 261.5 | J9: ='The 3-Statement Projection'!I39+'The 3-Statement Projection'!I45+'The 3-Statement Projection'!I46 -> 216.5 | ... L9: ='The 3-Statement Projection'!K39+'The 3-Statement Projection'!K45+'The 3-Statement Projection'!K46 -> 126.5
B10: ROCE (%) | C10: ='The 3-Statement Projection'!B19/('The 3-Statement Projection'!B36+'The 3-Statement Projection'!B42) -> 0.11487105 | D10: ='The 3-Statement Projection'!C19/('The 3-Statement Projection'!C36+'The 3-Statement Projection'!C42) -> 0.12937162 | E10: ='The 3-Statement Projection'!D19/('The 3-Statement Projection'!D36+'The 3-Statement Projection'!D42) -> 0.26225183 | F10: ='The 3-Statement Projection'!E19/('The 3-Statement Projection'!E36+'The 3-Statement Projection'!E42) -> 0.22886099 | G10: ='The 3-Statement Projection'!F19/('The 3-Statement Projection'!F36+'The 3-Statement Projection'!F42) -> 0.21680431 | H10: ='The 3-Statement Projection'!G19/('The 3-Statement Projection'!G36+'The 3-Statement Projection'!G42) -> 0.20579064 | I10: ='The 3-Statement Projection'!H19/('The 3-Statement Projection'!H36+'The 3-Statement Projection'!H42) -> 0.19323932 | J10: ='The 3-Statement Projection'!I19/('The 3-Statement Projection'!I36+'The 3-Statement Projection'!I42) -> 0.18196167 | ... L10: ='The 3-Statement Projection'!K19/('The 3-Statement Projection'!K36+'The 3-Statement Projection'!K42) -> 0.16249584
B12: 1b. MACRO & FOREX SENSITIVITY
B13: Assumed USD/INR Rate | C13: n/a | D13: ='Assumptions & Drivers'!D15 -> 85 | E13: ='Assumptions & Drivers'!E15 -> 85 | F13: ='Assumptions & Drivers'!F15 -> 85 | G13: ='Assumptions & Drivers'!G15 -> 85 | H13: ='Assumptions & Drivers'!H15 -> 85 | I13: ='Assumptions & Drivers'!I15 -> 85 | J13: ='Assumptions & Drivers'!J15 -> 85 | K13: ='Assumptions & Drivers'!K15 -> 85 | L13: ='Assumptions & Drivers'!L15 -> 85
B14: Coking Coal (USD/MT) | C14: n/a | D14: ='Assumptions & Drivers'!D16 -> 170 | E14: ='Assumptions & Drivers'!E16 -> 170 | F14: ='Assumptions & Drivers'!F16 -> 170 | G14: ='Assumptions & Drivers'!G16 -> 170 | H14: ='Assumptions & Drivers'!H16 -> 170 | I14: ='Assumptions & Drivers'!I16 -> 170 | J14: ='Assumptions & Drivers'!J16 -> 170 | K14: ='Assumptions & Drivers'!K16 -> 170 | L14: ='Assumptions & Drivers'!L16 -> 170
B16: 2. PERFORMANCE CHARTS
A19: Base Case (WACC = 12.5%, g = 0.0%)
B51: 3. DCF VALUATION OUTPUT
B52: Implied Intrinsic Value per Share | C52: ='WACC & DCF Valuation'!B81 -> 514.75362 | E52: WACC: | F52: ='WACC & DCF Valuation'!B32 -> 0.12514351 | G52: Terminal g: | H52: ='WACC & DCF Valuation'!B56 -> 0
B53: Conservative Value per Share (WACC 14.1%) | C53: ='WACC & DCF Valuation'!B149 -> 458.75388 | E53: WACC: | F53: ='WACC & DCF Valuation'!B108 -> 0.141
B54: CHART DATA — DO NOT EDIT
B56: Chart 1: Revenue & Growth
C57: FY24A | D57: FY25A | E57: FY26E | F57: FY27E | G57: FY28E | H57: FY29E | I57: FY30E | J57: FY31E | K57: FY32E | L57: FY33E
B58: Revenue (₹ Cr) | C58: =C6 -> 1572.8 | D58: =D6 -> 1871.33 | E58: =E6 -> 2081.1111 | F58: =F6 -> 2195.6111 | G58: =G6 -> 2195.6111 | H58: =H6 -> 2195.6111 | I58: =I6 -> 2195.6111 | J58: =J6 -> 2195.6111 | ... L58: =L6 -> 2195.6111
B59: YoY Growth (%) | D59: ='The 3-Statement Projection'!C7 -> 0.18980799 | E59: ='The 3-Statement Projection'!D7 -> 0.11210268 | F59: ='The 3-Statement Projection'!E7 -> 0.055018677 | G59: ='The 3-Statement Projection'!F7 -> 0 | H59: ='The 3-Statement Projection'!G7 -> 0 | I59: ='The 3-Statement Projection'!H7 -> 0 | J59: ='The 3-Statement Projection'!I7 -> 0 | K59: ='The 3-Statement Projection'!J7 -> 0 | L59: ='The 3-Statement Projection'!K7 -> 0
B62: Chart 2: Margin Expansion
C63: FY24A | D63: FY25A | E63: FY26E | F63: FY27E | G63: FY28E | H63: FY29E | I63: FY30E | J63: FY31E | K63: FY32E | L63: FY33E
B64: Gross Margin | C64: ='The 3-Statement Projection'!B10/'The 3-Statement Projection'!B6 -> 0.15022889 | D64: ='The 3-Statement Projection'!C10/'The 3-Statement Projection'!C6 -> 0.15809077 | E64: ='The 3-Statement Projection'!D10/'The 3-Statement Projection'!D6 -> 0.22917245 | F64: ='The 3-Statement Projection'!E10/'The 3-Statement Projection'!E6 -> 0.21076871 | G64: ='The 3-Statement Projection'!F10/'The 3-Statement Projection'!F6 -> 0.21276871 | H64: ='The 3-Statement Projection'!G10/'The 3-Statement Projection'!G6 -> 0.21476871 | I64: ='The 3-Statement Projection'!H10/'The 3-Statement Projection'!H6 -> 0.21476871 | J64: ='The 3-Statement Projection'!I10/'The 3-Statement Projection'!I6 -> 0.21476871 | ... L64: ='The 3-Statement Projection'!K10/'The 3-Statement Projection'!K6 -> 0.21476871
B65: EBITDA Margin | C65: =C7 -> 0.10350966 | D65: =D7 -> 0.10711099 | E65: =E7 -> 0.18247245 | F65: =F7 -> 0.16406871 | G65: =G7 -> 0.16606871 | H65: =H7 -> 0.16806871 | I65: =I7 -> 0.16806871 | J65: =J7 -> 0.16806871 | ... L65: =L7 -> 0.16806871
B66: Net Margin | C66: ='The 3-Statement Projection'!B28 -> 0.060967701 | D66: ='The 3-Statement Projection'!C28 -> 0.061239867 | E66: ='The 3-Statement Projection'!D28 -> 0.10850486 | F66: ='The 3-Statement Projection'!E28 -> 0.090988844 | G66: ='The 3-Statement Projection'!F28 -> 0.095803008 | H66: ='The 3-Statement Projection'!G28 -> 0.098296639 | I66: ='The 3-Statement Projection'!H28 -> 0.099232054 | J66: ='The 3-Statement Projection'!I28 -> 0.10015163 | ... L66: ='The 3-Statement Projection'!K28 -> 0.10195593
B69: Chart 3: Debt vs Cash (Deleveraging)
C70: FY24A | D70: FY25A | E70: FY26E | F70: FY27E | G70: FY28E | H70: FY29E | I70: FY30E | J70: FY31E | K70: FY32E | L70: FY33E
B71: Total Debt | C71: =C9 -> 324.82 | D71: =D9 -> 545.82 | E71: =E9 -> 613.1 | F71: =F9 -> 419.11871 | G71: =G9 -> 351.8 | H71: =H9 -> 306.5 | I71: =I9 -> 261.5 | J71: =J9 -> 216.5 | ... L71: =L9 -> 126.5
B72: Cash & Bank Balance | C72: ='The 3-Statement Projection'!B67 -> 74.8 | D72: ='The 3-Statement Projection'!C67 -> 210.18 | E72: ='The 3-Statement Projection'!D67 -> 32.122825 | F72: ='The 3-Statement Projection'!E67 -> 20 | G72: ='The 3-Statement Projection'!F67 -> 298.26036 | H72: ='The 3-Statement Projection'!G67 -> 447.28284 | I72: ='The 3-Statement Projection'!H67 -> 591.82165 | J72: ='The 3-Statement Projection'!I67 -> 734.66564 | ... L72: ='The 3-Statement Projection'!K67 -> 980.69601
B73: Net Debt | C73: =C71-C72 -> 250.02 | D73: =D71-D72 -> 335.64 | E73: =E71-E72 -> 580.97717 | F73: =F71-F72 -> 399.11871 | G73: =G71-G72 -> 53.539645 | H73: =H71-H72 -> -140.78284 | I73: =I71-I72 -> -330.32165 | J73: =J71-J72 -> -518.16564 | ... L73: =L71-L72 -> -854.19601
B76: Chart 4: Valuation Football Field
C77: Low (₹) | D77: Base - Low | E77: High - Base
B78: Bear (WACC+1%, g 0%) | C78: ='Sensitivity Analysis'!B15 -> 465.82131 | D78: ='Sensitivity Analysis'!D15-'Sensitivity Analysis'!B15 -> 42.875385 | E78: ='Sensitivity Analysis'!F15-'Sensitivity Analysis'!D15 -> 60.900948
B79: Moderate Bear | C79: ='Sensitivity Analysis'!B14 -> 489.35898 | D79: ='Sensitivity Analysis'!D14-'Sensitivity Analysis'!B14 -> 48.004449 | E79: ='Sensitivity Analysis'!F14-'Sensitivity Analysis'!D14 -> 69.305793
B80: Base Case | C80: ='Sensitivity Analysis'!B13 -> 514.75362 | D80: ='Sensitivity Analysis'!D13-'Sensitivity Analysis'!B13 -> 53.94508 | E80: ='Sensitivity Analysis'!F13-'Sensitivity Analysis'!D13 -> 79.288212
B81: Moderate Bull | C81: ='Sensitivity Analysis'!B12 -> 542.23561 | D81: ='Sensitivity Analysis'!D12-'Sensitivity Analysis'!B12 -> 60.863831 | E81: ='Sensitivity Analysis'!F12-'Sensitivity Analysis'!D12 -> 91.241254
B82: Bull (WACC-1%, g 4%) | C82: ='Sensitivity Analysis'!B11 -> 572.07529 | D82: ='Sensitivity Analysis'!D11-'Sensitivity Analysis'!B11 -> 68.970618 | E82: ='Sensitivity Analysis'!F11-'Sensitivity Analysis'!D11 -> 105.6847
B83: Lender/Conservative (WACC 14.1%) | C83: ='WACC & DCF Valuation'!F156 -> 458.75388 | D83: =C80-C83 -> 55.999734 | E83: 0
...

Sheet Historical FS
B2: ="Historical Financial Statements - "&'Executive Summary'!B2 -> Historical Financial Statements - Jindal Coke Ltd.
B3: Years | C3: ='Income and Expenditure Summary'!C4 -> FY16A | D3: ='Income and Expenditure Summary'!D4 -> FY17A | E3: ='Income and Expenditure Summary'!E4 -> FY18A | F3: ='Income and Expenditure Summary'!F4 -> FY19A | G3: ='Income and Expenditure Summary'!G4 -> FY20A | H3: ='Income and Expenditure Summary'!H4 -> FY21A | I3: ='Income and Expenditure Summary'!I4 -> FY22A | J3: ='Income and Expenditure Summary'!J4 -> FY23A | ... L3: ='Income and Expenditure Summary'!L4 -> FY25A | M3: Formula Reference
A4: # | B4: Income Statement
B5: Net Sales | C5: =IFERROR(SUM('Income and Expenditure Summary'!C10:C11)-'Income and Expenditure Summary'!C28,0) -> 358.26 | D5: =IFERROR(SUM('Income and Expenditure Summary'!D10:D11)-'Income and Expenditure Summary'!D28,0) -> 656.45 | E5: =IFERROR(SUM('Income and Expenditure Summary'!E10:E11)-'Income and Expenditure Summary'!E28,0) -> 888.16 | F5: =IFERROR(SUM('Income and Expenditure Summary'!F10:F11)-'Income and Expenditure Summary'!F28,0) -> 937.12 | G5: =IFERROR(SUM('Income and Expenditure Summary'!G10:G11)-'Income and Expenditure Summary'!G28,0) -> 761.73 | H5: =IFERROR(SUM('Income and Expenditure Summary'!H10:H11)-'Income and Expenditure Summary'!H28,0) -> 763.42 | I5: =IFERROR(SUM('Income and Expenditure Summary'!I10:I11)-'Income and Expenditure Summary'!I28,0) -> 1242.06 | J5: =IFERROR(SUM('Income and Expenditure Summary'!J10:J11)-'Income and Expenditure Summary'!J28,0) -> 1993.14 | ... L5: =IFERROR(SUM('Income and Expenditure Summary'!L10:L11)-'Income and Expenditure Summary'!L28,0) -> 1871.33 | M5: Net Sales = Industrial Sales + Income from Non-Financial Services - Indirect Taxes
B6: Sales Growth | C6: - | D6: =IFERROR(D5/C5 -1,0) -> 0.83232848 | E6: =IFERROR(E5/D5 -1,0) -> 0.35297433 | F6: =IFERROR(F5/E5 -1,0) -> 0.055125203 | G6: =IFERROR(G5/F5 -1,0) -> -0.18715853 | H6: =IFERROR(H5/G5 -1,0) -> 0.0022186339 | I6: =IFERROR(I5/H5 -1,0) -> 0.62696812 | J6: =IFERROR(J5/I5 -1,0) -> 0.60470509 | K6: =IFERROR(K5/J5 -1,0) -> -0.21089336 | L6: =IFERROR(L5/K5 -1,0) -> 0.18980799 | M6: Sales Growth = (Net Sales / Prior Year Net Sales) - 1
B8: COGS | C8: =IFERROR('Income and Expenditure Summary'!C22-'Income and Expenditure Summary'!C27-'Income and Expenditure Summary'!C28-SUM('Income and Expenditure Summary'!C30:C32,'Income and Expenditure Summary'!C34:C41)-'Income and Expenditure Summary'!C19,0) -> 337.43 | D8: =IFERROR('Income and Expenditure Summary'!D22-'Income and Expenditure Summary'!D27-'Income and Expenditure Summary'!D28-SUM('Income and Expenditure Summary'!D30:D32,'Income and Expenditure Summary'!D34:D41)-'Income and Expenditure Summary'!D19,0) -> 515.51 | E8: =IFERROR('Income and Expenditure Summary'!E22-'Income and Expenditure Summary'!E27-'Income and Expenditure Summary'!E28-SUM('Income and Expenditure Summary'!E30:E32,'Income and Expenditure Summary'!E34:E41)-'Income and Expenditure Summary'!E19,0) -> 682.56 | F8: =IFERROR('Income and Expenditure Summary'!F22-'Income and Expenditure Summary'!F27-'Income and Expenditure Summary'!F28-SUM('Income and Expenditure Summary'!F30:F32,'Income and Expenditure Summary'!F34:F41)-'Income and Expenditure Summary'!F19,0) -> 754.55 | G8: =IFERROR('Income and Expenditure Summary'!G22-'Income and Expenditure Summary'!G27-'Income and Expenditure Summary'!G28-SUM('Income and Expenditure Summary'!G30:G32,'Income and Expenditure Summary'!G34:G41)-'Income and Expenditure Summary'!G19,0) -> 665.53 | H8: =IFERROR('Income and Expenditure Summary'!H22-'Income and Expenditure Summary'!H27-'Income and Expenditure Summary'!H28-SUM('Income and Expenditure Summary'!H30:H32,'Income and Expenditure Summary'!H34:H41)-'Income and Expenditure Summary'!H19,0) -> 569.84 | I8: =IFERROR('Income and Expenditure Summary'!I22-'Income and Expenditure Summary'!I27-'Income and Expenditure Summary'!I28-SUM('Income and Expenditure Summary'!I30:I32,'Income and Expenditure Summary'!I34:I41)-'Income and Expenditure Summary'!I19,0) -> 807 | J8: =IFERROR('Income and Expenditure Summary'!J22-'Income and Expenditure Summary'!J27-'Income and Expenditure Summary'!J28-SUM('Income and Expenditure Summary'!J30:J32,'Income and Expenditure Summary'!J34:J41)-'Income and Expenditure Summary'!J19,0) -> 1670.8 | ... L8: =IFERROR('Income and Expenditure Summary'!L22-'Income and Expenditure Summary'!L27-'Income and Expenditure Summary'!L28-SUM('Income and Expenditure Summary'!L30:L32,'Income and Expenditure Summary'!L34:L41)-'Income and Expenditure Summary'!L19,0) -> 1575.49 | M8: COGS = Total Operating Expenses - Employee Benefit - Indirect Taxes - SG&A Items - Change in Stock
B9: COGS % Sales | C9: =IFERROR(C8/C5,0) -> 0.94185787 | D9: =IFERROR(D8/D5,0) -> 0.78529972 | E9: =IFERROR(E8/E5,0) -> 0.76851018 | F9: =IFERROR(F8/F5,0) -> 0.8051797 | G9: =IFERROR(G8/G5,0) -> 0.87370853 | H9: =IFERROR(H8/H5,0) -> 0.74643054 | I9: =IFERROR(I8/I5,0) -> 0.64972707 | J9: =IFERROR(J8/J5,0) -> 0.83827528 | ... L9: =IFERROR(L8/L5,0) -> 0.84190923 | M9: COGS % Sales = COGS / Net Sales
B11: Gross Profit | C11: =IFERROR(C5-C8,0) -> 20.83 | D11: =IFERROR(D5-D8,0) -> 140.94 | E11: =IFERROR(E5-E8,0) -> 205.6 | F11: =IFERROR(F5-F8,0) -> 182.57 | G11: =IFERROR(G5-G8,0) -> 96.2 | H11: =IFERROR(H5-H8,0) -> 193.58 | I11: =IFERROR(I5-I8,0) -> 435.06 | J11: =IFERROR(J5-J8,0) -> 322.34 | ... L11: =IFERROR(L5-L8,0) -> 295.84 | M11: Gross Profit = Net Sales - COGS
B12: Gross Profit Margin | C12: =IFERROR(C11/C5,0) -> 0.058142131 | D12: =IFERROR(D11/D5,0) -> 0.21470028 | E12: =IFERROR(E11/E5,0) -> 0.23148982 | F12: =IFERROR(F11/F5,0) -> 0.1948203 | G12: =IFERROR(G11/G5,0) -> 0.12629147 | H12: =IFERROR(H11/H5,0) -> 0.25356946 | I12: =IFERROR(I11/I5,0) -> 0.35027293 | J12: =IFERROR(J11/J5,0) -> 0.16172472 | ... L12: =IFERROR(L11/L5,0) -> 0.15809077 | M12: Gross Profit Margin = Gross Profit / Net Sales
B14: Employee Benefit Expenses | C14: =IFERROR('Income and Expenditure Summary'!C27,0) -> 7.13 | D14: =IFERROR('Income and Expenditure Summary'!D27,0) -> 9.43 | E14: =IFERROR('Income and Expenditure Summary'!E27,0) -> 8.19 | F14: =IFERROR('Income and Expenditure Summary'!F27,0) -> 9.75 | G14: =IFERROR('Income and Expenditure Summary'!G27,0) -> 10.08 | H14: =IFERROR('Income and Expenditure Summary'!H27,0) -> 10.28 | I14: =IFERROR('Income and Expenditure Summary'!I27,0) -> 12.84 | J14: =IFERROR('Income and Expenditure Summary'!J27,0) -> 12.16 | ... L14: =IFERROR('Income and Expenditure Summary'!L27,0) -> 17.85 | M14: Employee Benefit Expenses = Sourced from I&E Summary (Compensation to Employees)
B15: Employee Benefit Exp % Sales | C15: =IFERROR(C14/C5,0) -> 0.019901747 | D15: =IFERROR(D14/D5,0) -> 0.014365146 | E15: =IFERROR(E14/E5,0) -> 0.0092213115 | F15: =IFERROR(F14/F5,0) -> 0.010404217 | G15: =IFERROR(G14/G5,0) -> 0.013233035 | H15: =IFERROR(H14/H5,0) -> 0.01346572 | I15: =IFERROR(I14/I5,0) -> 0.010337665 | J15: =IFERROR(J14/J5,0) -> 0.0061009262 | ... L15: =IFERROR(L14/L5,0) -> 0.0095386704 | M15: Employee Benefit Exp % Sales = Employee Benefit Expenses / Net Sales
B17: Selling, General & Admin Expenses | C17: =IFERROR(SUM('Income and Expenditure Summary'!C29:C32,'Income and Expenditure Summary'!C34:C41),0) -> 18.86 | D17: =IFERROR(SUM('Income and Expenditure Summary'!D29:D32,'Income and Expenditure Summary'!D34:D41),0) -> 21.88 | E17: =IFERROR(SUM('Income and Expenditure Summary'!E29:E32,'Income and Expenditure Summary'!E34:E41),0) -> 34.41 | F17: =IFERROR(SUM('Income and Expenditure Summary'!F29:F32,'Income and Expenditure Summary'!F34:F41),0) -> 41.49 | G17: =IFERROR(SUM('Income and Expenditure Summary'!G29:G32,'Income and Expenditure Summary'!G34:G41),0) -> 35.32 | H17: =IFERROR(SUM('Income and Expenditure Summary'!H29:H32,'Income and Expenditure Summary'!H34:H41),0) -> 35.71 | I17: =IFERROR(SUM('Income and Expenditure Summary'!I29:I32,'Income and Expenditure Summary'!I34:I41),0) -> 45.81 | J17: =IFERROR(SUM('Income and Expenditure Summary'!J29:J32,'Income and Expenditure Summary'!J34:J41),0) -> 50.25 | ... L17: =IFERROR(SUM('Income and Expenditure Summary'!L29:L32,'Income and Expenditure Summary'!L34:L41),0) -> 77.55 | M17: SG&A Expenses = Rent + Repairs + Insurance + Professional Fees + Directors Fees + Selling & Distribution + Travel + Communications + Miscellaneous + Other Operational
B18: S,G&A % Sales | C18: =IFERROR(C17/C5,0) -> 0.052643332 | D18: =IFERROR(D17/D5,0) -> 0.033330794 | E18: =IFERROR(E17/E5,0) -> 0.038743019 | F18: =IFERROR(F17/F5,0) -> 0.044273946 | G18: =IFERROR(G17/G5,0) -> 0.046368136 | H18: =IFERROR(H17/H5,0) -> 0.046776349 | I18: =IFERROR(I17/I5,0) -> 0.036882276 | J18: =IFERROR(J17/J5,0) -> 0.025211475 | ... L18: =IFERROR(L17/L5,0) -> 0.041441114 | M18: SG&A % Sales = SG&A Expenses / Net Sales
B20: EBITDA | C20: =IFERROR(C11-C14-C17,0) -> -5.16 | D20: =IFERROR(D11-D14-D17,0) -> 109.63 | E20: =IFERROR(E11-E14-E17,0) -> 163 | F20: =IFERROR(F11-F14-F17,0) -> 131.33 | G20: =IFERROR(G11-G14-G17,0) -> 50.8 | H20: =IFERROR(H11-H14-H17,0) -> 147.59 | I20: =IFERROR(I11-I14-I17,0) -> 376.41 | J20: =IFERROR(J11-J14-J17,0) -> 259.93 | ... L20: =IFERROR(L11-L14-L17,0) -> 200.44 | M20: EBITDA = Gross Profit - Employee Benefit Expenses - SG&A Expenses
B21: EBITDA Margin | C21: =IFERROR(C20/C5,0) -> -0.014402948 | D21: =IFERROR(D20/D5,0) -> 0.16700434 | E21: =IFERROR(E20/E5,0) -> 0.18352549 | F21: =IFERROR(F20/F5,0) -> 0.14014214 | G21: =IFERROR(G20/G5,0) -> 0.066690297 | H21: =IFERROR(H20/H5,0) -> 0.1933274 | I21: =IFERROR(I20/I5,0) -> 0.30305299 | J21: =IFERROR(J20/J5,0) -> 0.13041231 | ... L21: =IFERROR(L20/L5,0) -> 0.10711099 | M21: EBITDA Margin = EBITDA / Net Sales
B23: Depreciation | C23: =IFERROR('Income and Expenditure Summary'!C47,0) -> 29.11 | D23: =IFERROR('Income and Expenditure Summary'!D47,0) -> 29.34 | E23: =IFERROR('Income and Expenditure Summary'!E47,0) -> 27.29 | F23: =IFERROR('Income and Expenditure Summary'!F47,0) -> 17.23 | G23: =IFERROR('Income and Expenditure Summary'!G47,0) -> 17.96 | H23: =IFERROR('Income and Expenditure Summary'!H47,0) -> 19.99 | I23: =IFERROR('Income and Expenditure Summary'!I47,0) -> 21.21 | J23: =IFERROR('Income and Expenditure Summary'!J47,0) -> 21.45 | ... L23: =IFERROR('Income and Expenditure Summary'!L47,0) -> 30.98 | M23: Depreciation = Sourced from I&E Summary (Depreciation under Non-Cash Charges)
B24: Depreciation % Sales | C24: =IFERROR(C23/C5,0) -> 0.081253838 | D24: =IFERROR(D23/D5,0) -> 0.04469495 | E24: =IFERROR(E23/E5,0) -> 0.030726446 | F24: =IFERROR(F23/F5,0) -> 0.018386119 | G24: =IFERROR(G23/G5,0) -> 0.023577908 | H24: =IFERROR(H23/H5,0) -> 0.0261848 | I24: =IFERROR(I23/I5,0) -> 0.01707647 | J24: =IFERROR(J23/J5,0) -> 0.010761913 | ... L24: =IFERROR(L23/L5,0) -> 0.01655507 | M24: Depreciation % Sales = Depreciation / Net Sales
B26: EBIT | C26: =IFERROR(C20-C23,0) -> -34.27 | D26: =IFERROR(D20-D23,0) -> 80.29 | E26: =IFERROR(E20-E23,0) -> 135.71 | F26: =IFERROR(F20-F23,0) -> 114.1 | G26: =IFERROR(G20-G23,0) -> 32.84 | H26: =IFERROR(H20-H23,0) -> 127.6 | I26: =IFERROR(I20-I23,0) -> 355.2 | J26: =IFERROR(J20-J23,0) -> 238.48 | ... L26: =IFERROR(L20-L23,0) -> 169.46 | M26: EBIT = EBITDA - Depreciation
B27: EBIT Margin | C27: =IFERROR(C26/C5,0) -> -0.095656786 | D27: =IFERROR(D26/D5,0) -> 0.12230939 | E27: =IFERROR(E26/E5,0) -> 0.15279905 | F27: =IFERROR(F26/F5,0) -> 0.12175602 | G27: =IFERROR(G26/G5,0) -> 0.043112389 | H27: =IFERROR(H26/H5,0) -> 0.1671426 | I27: =IFERROR(I26/I5,0) -> 0.28597652 | J27: =IFERROR(J26/J5,0) -> 0.1196504 | ... L27: =IFERROR(L26/L5,0) -> 0.090555915 | M27: EBIT Margin = EBIT / Net Sales
B29: Finance Costs | C29: =IFERROR(SUM('Income and Expenditure Summary'!C45:C46),0) -> 9.31 | D29: =IFERROR(SUM('Income and Expenditure Summary'!D45:D46),0) -> 53.01 | E29: =IFERROR(SUM('Income and Expenditure Summary'!E45:E46),0) -> 59.95 | F29: =IFERROR(SUM('Income and Expenditure Summary'!F45:F46),0) -> 55.18 | G29: =IFERROR(SUM('Income and Expenditure Summary'!G45:G46),0) -> 51.75 | H29: =IFERROR(SUM('Income and Expenditure Summary'!H45:H46),0) -> 50.96 | I29: =IFERROR(SUM('Income and Expenditure Summary'!I45:I46),0) -> 34.91 | J29: =IFERROR(SUM('Income and Expenditure Summary'!J45:J46),0) -> 33.2 | ... L29: =IFERROR(SUM('Income and Expenditure Summary'!L45:L46),0) -> 33.51 | M29: Finance Costs = Fee Based Financial Services Expenses + Fund Based Financial Services Expenses
B30: Finance Costs % Sales | C30: =IFERROR(C29/C5,0) -> 0.025986714 | D30: =IFERROR(D29/D5,0) -> 0.080752533 | E30: =IFERROR(E29/E5,0) -> 0.067499099 | F30: =IFERROR(F29/F5,0) -> 0.058882534 | G30: =IFERROR(G29/G5,0) -> 0.067937458 | H30: =IFERROR(H29/H5,0) -> 0.066752246 | I30: =IFERROR(I29/I5,0) -> 0.028106533 | J30: =IFERROR(J29/J5,0) -> 0.016657134 | ... L30: =IFERROR(L29/L5,0) -> 0.01790705 | M30: Finance Costs % Sales = Finance Costs / Net Sales
B32: Other income | C32: =IFERROR('Income and Expenditure Summary'!C12+'Income and Expenditure Summary'!C16,0) -> 0 | D32: =IFERROR('Income and Expenditure Summary'!D12+'Income and Expenditure Summary'!D16,0) -> 8.62 | E32: =IFERROR('Income and Expenditure Summary'!E12+'Income and Expenditure Summary'!E16,0) -> 6.08 | F32: =IFERROR('Income and Expenditure Summary'!F12+'Income and Expenditure Summary'!F16,0) -> 5.47 | G32: =IFERROR('Income and Expenditure Summary'!G12+'Income and Expenditure Summary'!G16,0) -> 5.01 | H32: =IFERROR('Income and Expenditure Summary'!H12+'Income and Expenditure Summary'!H16,0) -> 3.37 | I32: =IFERROR('Income and Expenditure Summary'!I12+'Income and Expenditure Summary'!I16,0) -> 4.98 | J32: =IFERROR('Income and Expenditure Summary'!J12+'Income and Expenditure Summary'!J16,0) -> 14.3 | ... L32: =IFERROR('Income and Expenditure Summary'!L12+'Income and Expenditure Summary'!L16,0) -> 18.7 | M32: Other Income = Income from Financial Services + Other Income
B33: Other Income % Sales | C33: =IFERROR(C32/C5,0) -> 0 | D33: =IFERROR(D32/D5,0) -> 0.013131236 | E33: =IFERROR(E32/E5,0) -> 0.0068456134 | F33: =IFERROR(F32/F5,0) -> 0.0058370326 | G33: =IFERROR(G32/G5,0) -> 0.0065771336 | H33: =IFERROR(H32/H5,0) -> 0.004414346 | I33: =IFERROR(I32/I5,0) -> 0.0040094681 | J33: =IFERROR(J32/J5,0) -> 0.0071746089 | ... L33: =IFERROR(L32/L5,0) -> 0.0099928928 | M33: Other Income % Sales = Other Income / Net Sales
B35: Net Extraordinary Items | C35: =IFERROR('Income and Expenditure Summary'!C17-'Income and Expenditure Summary'!C53,0) -> -5.46 | D35: =IFERROR('Income and Expenditure Summary'!D17-'Income and Expenditure Summary'!D53,0) -> 1.13 | E35: =IFERROR('Income and Expenditure Summary'!E17-'Income and Expenditure Summary'!E53,0) -> 1.56 | F35: =IFERROR('Income and Expenditure Summary'!F17-'Income and Expenditure Summary'!F53,0) -> 0.1 | G35: =IFERROR('Income and Expenditure Summary'!G17-'Income and Expenditure Summary'!G53,0) -> 0.2 | H35: =IFERROR('Income and Expenditure Summary'!H17-'Income and Expenditure Summary'!H53,0) -> 2.95 | I35: =IFERROR('Income and Expenditure Summary'!I17-'Income and Expenditure Summary'!I53,0) -> 3.95 | J35: =IFERROR('Income and Expenditure Summary'!J17-'Income and Expenditure Summary'!J53,0) -> 0 | ... L35: =IFERROR('Income and Expenditure Summary'!L17-'Income and Expenditure Summary'!L53,0) -> 0 | M35: Net Extraordinary Items = Prior Period & Extraordinary Income - Prior Period & Extraordinary Expenses
B37: Profit Before Tax | C37: =IFERROR(SUM(C26,C32,C35)-C29,0) -> -49.04 | D37: =IFERROR(SUM(D26,D32,D35)-D29,0) -> 37.03 | E37: =IFERROR(SUM(E26,E32,E35)-E29,0) -> 83.4 | F37: =IFERROR(SUM(F26,F32,F35)-F29,0) -> 64.49 | G37: =IFERROR(SUM(G26,G32,G35)-G29,0) -> -13.7 | H37: =IFERROR(SUM(H26,H32,H35)-H29,0) -> 82.96 | I37: =IFERROR(SUM(I26,I32,I35)-I29,0) -> 329.22 | J37: =IFERROR(SUM(J26,J32,J35)-J29,0) -> 219.58 | ... L37: =IFERROR(SUM(L26,L32,L35)-L29,0) -> 154.65 | M37: Profit Before Tax = EBIT + Other Income + Net Extraordinary Items - Finance Costs
B38: PBT % Sales | C38: =IFERROR(C37/C5,0) -> -0.13688383 | D38: =IFERROR(D37/D5,0) -> 0.056409475 | E38: =IFERROR(E37/E5,0) -> 0.093902 | F38: =IFERROR(F37/F5,0) -> 0.068817227 | G38: =IFERROR(G37/G5,0) -> -0.017985375 | H38: =IFERROR(H37/H5,0) -> 0.10866888 | I38: =IFERROR(I37/I5,0) -> 0.26505966 | J38: =IFERROR(J37/J5,0) -> 0.11016788 | ... L38: =IFERROR(L37/L5,0) -> 0.082641757 | M38: PBT % Sales = Profit Before Tax / Net Sales
B40: Provision for Direct Tax | C40: =IFERROR('Income and Expenditure Summary'!C55,0) -> -16.97 | D40: =IFERROR('Income and Expenditure Summary'!D55,0) -> 12.86 | E40: =IFERROR('Income and Expenditure Summary'!E55,0) -> 26.23 | F40: =IFERROR('Income and Expenditure Summary'!F55,0) -> 24.38 | G40: =IFERROR('Income and Expenditure Summary'!G55,0) -> -1.95 | H40: =IFERROR('Income and Expenditure Summary'!H55,0) -> 25.1 | I40: =IFERROR('Income and Expenditure Summary'!I55,0) -> 90.41 | J40: =IFERROR('Income and Expenditure Summary'!J55,0) -> 54.6 | ... L40: =IFERROR('Income and Expenditure Summary'!L55,0) -> 40.05 | M40: Provision for Direct Tax = Sourced from I&E Summary (Provision for Direct Tax)
B42: Profit After Tax | C42: =IFERROR(C37-C40,0) -> -32.07 | D42: =IFERROR(D37-D40,0) -> 24.17 | E42: =IFERROR(E37-E40,0) -> 57.17 | F42: =IFERROR(F37-F40,0) -> 40.11 | G42: =IFERROR(G37-G40,0) -> -11.75 | H42: =IFERROR(H37-H40,0) -> 57.86 | I42: =IFERROR(I37-I40,0) -> 238.81 | J42: =IFERROR(J37-J40,0) -> 164.98 | ... L42: =IFERROR(L37-L40,0) -> 114.6 | M42: Profit After Tax = Profit Before Tax - Provision for Direct Tax
B43: Net Income Margin | C43: =IFERROR(C42/C5,0) -> -0.089515994 | D43: =IFERROR(D42/D5,0) -> 0.036819255 | E43: =IFERROR(E42/E5,0) -> 0.064369033 | F43: =IFERROR(F42/F5,0) -> 0.042801349 | G43: =IFERROR(G42/G5,0) -> -0.015425413 | H43: =IFERROR(H42/H5,0) -> 0.075790522 | I43: =IFERROR(I42/I5,0) -> 0.19226929 | J43: =IFERROR(J42/J5,0) -> 0.082773915 | ... L43: =IFERROR(L42/L5,0) -> 0.061239867 | M43: Net Income Margin = Profit After Tax / Net Sales
B45: Check: PAT (HFS vs I&E) | C45: =IF(ROUND(C42-'Income and Expenditure Summary'!C57,2)=0,"✓ Match","✗ Diff: "&TEXT(ROUND(C42-'Income and Expenditure Summary'!C57,2),"0.00")) -> ✓ Match | D45: =IF(ROUND(D42-'Income and Expenditure Summary'!D57,2)=0,"✓ Match","✗ Diff: "&TEXT(ROUND(D42-'Income and Expenditure Summary'!D57,2),"0.00")) -> ✓ Match | E45: =IF(ROUND(E42-'Income and Expenditure Summary'!E57,2)=0,"✓ Match","✗ Diff: "&TEXT(ROUND(E42-'Income and Expenditure Summary'!E57,2),"0.00")) -> ✓ Match | F45: =IF(ROUND(F42-'Income and Expenditure Summary'!F57,2)=0,"✓ Match","✗ Diff: "&TEXT(ROUND(F42-'Income and Expenditure Summary'!F57,2),"0.00")) -> ✓ Match | G45: =IF(ROUND(G42-'Income and Expenditure Summary'!G57,2)=0,"✓ Match","✗ Diff: "&TEXT(ROUND(G42-'Income and Expenditure Summary'!G57,2),"0.00")) -> ✓ Match | H45: =IF(ROUND(H42-'Income and Expenditure Summary'!H57,2)=0,"✓ Match","✗ Diff: "&TEXT(ROUND(H42-'Income and Expenditure Summary'!H57,2),"0.00")) -> ✓ Match | I45: =IF(ROUND(I42-'Income and Expenditure Summary'!I57,2)=0,"✓ Match","✗ Diff: "&TEXT(ROUND(I42-'Income and Expenditure Summary'!I57,2),"0.00")) -> ✓ Match | J45: =IF(ROUND(J42-'Income and Expenditure Summary'!J57,2)=0,"✓ Match","✗ Diff: "&TEXT(ROUND(J42-'Income and Expenditure Summary'!J57,2),"0.00")) -> ✓ Match | K45: =IF(ROUND(K42-'Income and Expenditure Summary'!K57,2)=0,"✓ Match","✗ Diff: "&TEXT(ROUND(K42-'Income and Expenditure Summary'!K57,2),"0.00")) -> ✓ Match | L45: =IF(ROUND(L42-'Income and Expenditure Summary'!L57,2)<=0.01,"✓ Match","✗ Diff: "&TEXT(ROUND(L42-'Income and Expenditure Summary'!L57,2),"0.00")) -> ✓ Match
A47: # | B47: Balance Sheet
B49: Equity & Liabilities
B51: Equity
B53: Share Capital | C53: =IFERROR('Balance Sheet Summary'!C10,0) -> 91.7 | D53: =IFERROR('Balance Sheet Summary'!D10,0) -> 141.7 | E53: =IFERROR('Balance Sheet Summary'!E10,0) -> 141.7 | F53: =IFERROR('Balance Sheet Summary'!F10,0) -> 141.7 | G53: =IFERROR('Balance Sheet Summary'!G10,0) -> 141.7 | H53: =IFERROR('Balance Sheet Summary'!H10,0) -> 141.69 | I53: =IFERROR('Balance Sheet Summary'!I10,0) -> 141.69 | J53: =IFERROR('Balance Sheet Summary'!J10,0) -> 141.69 | ... L53: =IFERROR('Balance Sheet Summary'!L10,0) -> 134.85
B54: Reserves & Surplus | C54: =IFERROR('Balance Sheet Summary'!C16,0) -> -6.11 | D54: =IFERROR('Balance Sheet Summary'!D16,0) -> -9.12 | E54: =IFERROR('Balance Sheet Summary'!E16,0) -> 110.03 | F54: =IFERROR('Balance Sheet Summary'!F16,0) -> 150.16 | G54: =IFERROR('Balance Sheet Summary'!G16,0) -> 138.35 | H54: =IFERROR('Balance Sheet Summary'!H16,0) -> 196.19 | I54: =IFERROR('Balance Sheet Summary'!I16,0) -> 434.96 | J54: =IFERROR('Balance Sheet Summary'!J16,0) -> 599.87 | ... L54: =IFERROR('Balance Sheet Summary'!L16,0) -> 662.75
B56: Total Equity | C56: =IFERROR(C53+C54,0) -> 85.59 | D56: =IFERROR(D53+D54,0) -> 132.58 | E56: =IFERROR(E53+E54,0) -> 251.73 | F56: =IFERROR(F53+F54,0) -> 291.86 | G56: =IFERROR(G53+G54,0) -> 280.05 | H56: =IFERROR(H53+H54,0) -> 337.88 | I56: =IFERROR(I53+I54,0) -> 576.65 | J56: =IFERROR(J53+J54,0) -> 741.56 | ... L56: =IFERROR(L53+L54,0) -> 797.6 | M56: Share Capital + Reserves and Surplus
B58: Non-Current Liabilities
B60: LT Borrowings (excl. current portion) | C60: =IFERROR('Balance Sheet Summary'!C26,0) -> 0 | D60: =IFERROR('Balance Sheet Summary'!D26,0) -> 488.17 | E60: =IFERROR('Balance Sheet Summary'!E26,0) -> 495.52 | F60: =IFERROR('Balance Sheet Summary'!F26,0) -> 408.05 | G60: =IFERROR('Balance Sheet Summary'!G26,0) -> 391.51 | H60: =IFERROR('Balance Sheet Summary'!H26,0) -> 387.8 | I60: =IFERROR('Balance Sheet Summary'!I26,0) -> 502.23 | J60: =IFERROR('Balance Sheet Summary'!J26,0) -> 324.03 | ... L60: =IFERROR('Balance Sheet Summary'!L26,0) -> 279.58
B61: Deferred Tax Liability | C61: =IFERROR('Balance Sheet Summary'!C35,0) -> 0 | D61: =IFERROR('Balance Sheet Summary'!D35,0) -> 0 | E61: =IFERROR('Balance Sheet Summary'!E35,0) -> 33.78 | F61: =IFERROR('Balance Sheet Summary'!F35,0) -> 44.17 | G61: =IFERROR('Balance Sheet Summary'!G35,0) -> 42.19 | H61: =IFERROR('Balance Sheet Summary'!H35,0) -> 53.07 | I61: =IFERROR('Balance Sheet Summary'!I35,0) -> 64.12 | J61: =IFERROR('Balance Sheet Summary'!J35,0) -> 66.09 | ... L61: =IFERROR('Balance Sheet Summary'!L35,0) -> 72.9
B62: Long-term Provisions | C62: =IFERROR('Balance Sheet Summary'!C37,0) -> 0.35 | D62: =IFERROR('Balance Sheet Summary'!D37,0) -> 0.69 | E62: =IFERROR('Balance Sheet Summary'!E37,0) -> 0.97 | F62: =IFERROR('Balance Sheet Summary'!F37,0) -> 1.05 | G62: =IFERROR('Balance Sheet Summary'!G37,0) -> 1.35 | H62: =IFERROR('Balance Sheet Summary'!H37,0) -> 1.44 | I62: =IFERROR('Balance Sheet Summary'!I37,0) -> 1.72 | J62: =IFERROR('Balance Sheet Summary'!J37,0) -> 1.82 | ... L62: =IFERROR('Balance Sheet Summary'!L37,0) -> 2.55
...

Sheet Ratio Analysis
B2: ="Ratio Analysis - "&'Executive Summary'!B2 -> Ratio Analysis - Jindal Coke Ltd.
B3: ='Historical FS'!B3 -> Years | C3: ='Historical FS'!C3 -> FY16A | D3: ='Historical FS'!D3 -> FY17A | E3: ='Historical FS'!E3 -> FY18A | F3: ='Historical FS'!F3 -> FY19A | G3: ='Historical FS'!G3 -> FY20A | H3: ='Historical FS'!H3 -> FY21A | I3: ='Historical FS'!I3 -> FY22A | ... L3: ='Historical FS'!L3 -> FY25A | M3: Trend (FY16→FY25) | N3: FY26E | O3: FY27E | P3: FY28E | Q3: FY29E | R3: FY30E | S3: FY31E | T3: FY32E | U3: FY33E | V3: Formula Reference | W3: Interpretation
B5: 1. Growth Ratios
B6: Sales Growth | C6: =IFERROR('Historical FS'!C6,0) -> - | D6: =IFERROR('Historical FS'!D6,0) -> 0.83232848 | E6: =IFERROR('Historical FS'!E6,0) -> 0.35297433 | F6: =IFERROR('Historical FS'!F6,0) -> 0.055125203 | G6: =IFERROR('Historical FS'!G6,0) -> -0.18715853 | H6: =IFERROR('Historical FS'!H6,0) -> 0.0022186339 | I6: =IFERROR('Historical FS'!I6,0) -> 0.62696812 | J6: =IFERROR('Historical FS'!J6,0) -> 0.60470509 | ... L6: =IFERROR('Historical FS'!L6,0) -> 0.18980799 | N6: =IFERROR(('The 3-Statement Projection'!D6/'The 3-Statement Projection'!C6)-1,0) -> 0.11210268 | O6: =IFERROR(('The 3-Statement Projection'!E6/'The 3-Statement Projection'!D6)-1,0) -> 0.055018677 | P6: =IFERROR(('The 3-Statement Projection'!F6/'The 3-Statement Projection'!E6)-1,0) -> 0 | Q6: =IFERROR(('The 3-Statement Projection'!G6/'The 3-Statement Projection'!F6)-1,0) -> 0 | R6: =IFERROR(('The 3-Statement Projection'!H6/'The 3-Statement Projection'!G6)-1,0) -> 0 | S6: =IFERROR(('The 3-Statement Projection'!I6/'The 3-Statement Projection'!H6)-1,0) -> 0 | T6: =IFERROR(('The 3-Statement Projection'!J6/'The 3-Statement Projection'!I6)-1,0) -> 0 | U6: =IFERROR(('The 3-Statement Projection'!K6/'The 3-Statement Projection'!J6)-1,0) -> 0 | V6: Sales Growth = (Net Sales CY / Net Sales PY) − 1 | W6: Sales growth is highly volatile, showing sharp spikes (FY17, FY22–23) and contractions (FY20, FY24), indicating cyclical demand or external shocks. The recovery in FY25 suggests stabilization, but inconsistency implies dependence on market conditions rather than steady organic growth.
B7: EBITDA Growth | C7: - | D7: =IF(OR('Historical FS'!C20<=0,'Historical FS'!D20<=0),"N/M",'Historical FS'!D20/'Historical FS'!C20 -1) -> N/M | E7: =IF(OR('Historical FS'!D20<=0,'Historical FS'!E20<=0),"N/M",'Historical FS'!E20/'Historical FS'!D20 -1) -> 0.4868193 | F7: =IF(OR('Historical FS'!E20<=0,'Historical FS'!F20<=0),"N/M",'Historical FS'!F20/'Historical FS'!E20 -1) -> -0.19429448 | G7: =IF(OR('Historical FS'!F20<=0,'Historical FS'!G20<=0),"N/M",'Historical FS'!G20/'Historical FS'!F20 -1) -> -0.61318815 | H7: =IF(OR('Historical FS'!G20<=0,'Historical FS'!H20<=0),"N/M",'Historical FS'!H20/'Historical FS'!G20 -1) -> 1.905315 | I7: =IF(OR('Historical FS'!H20<=0,'Historical FS'!I20<=0),"N/M",'Historical FS'!I20/'Historical FS'!H20 -1) -> 1.550376 | J7: =IFERROR('Historical FS'!J20/'Historical FS'!I20 -1,0) -> -0.3094498 | K7: =IFERROR('Historical FS'!K20/'Historical FS'!J20 -1,0) -> -0.37367753 | L7: =IFERROR('Historical FS'!L20/'Historical FS'!K20 -1,0) -> 0.23120393 | N7: =IFERROR('The 3-Statement Projection'!D15/'The 3-Statement Projection'!C15-1,0) -> 0.8945592 | O7: =IFERROR('The 3-Statement Projection'!E15/'The 3-Statement Projection'!D15-1,0) -> -0.051388043 | P7: =IFERROR('The 3-Statement Projection'!F15/'The 3-Statement Projection'!E15-1,0) -> 0.012190015 | Q7: =IFERROR('The 3-Statement Projection'!G15/'The 3-Statement Projection'!F15-1,0) -> 0.012043208 | R7: =IFERROR('The 3-Statement Projection'!H15/'The 3-Statement Projection'!G15-1,0) -> 0 | S7: =IFERROR('The 3-Statement Projection'!I15/'The 3-Statement Projection'!H15-1,0) -> 0 | T7: =IFERROR('The 3-Statement Projection'!J15/'The 3-Statement Projection'!I15-1,0) -> 0 | U7: =IFERROR('The 3-Statement Projection'!K15/'The 3-Statement Projection'!J15-1,0) -> 0 | V7: EBITDA Growth = (EBITDA CY / EBITDA PY) − 1 | W7: EBITDA growth is even more erratic than sales, with extreme swings (e.g., +190% in FY21, -61% in FY20), reflecting fluctuating operating efficiency. This indicates inconsistent cost control or operating leverage, where margins expand sharply in upcycles but compress significantly in downturns.
B8: EBIT Growth | C8: - | D8: =IF(OR('Historical FS'!C26<=0,'Historical FS'!D26<=0),"N/M",'Historical FS'!D26/'Historical FS'!C26 -1) -> N/M | E8: =IF(OR('Historical FS'!D26<=0,'Historical FS'!E26<=0),"N/M",'Historical FS'!E26/'Historical FS'!D26 -1) -> 0.69024785 | F8: =IF(OR('Historical FS'!E26<=0,'Historical FS'!F26<=0),"N/M",'Historical FS'!F26/'Historical FS'!E26 -1) -> -0.15923661 | G8: =IF(OR('Historical FS'!F26<=0,'Historical FS'!G26<=0),"N/M",'Historical FS'!G26/'Historical FS'!F26 -1) -> -0.7121823 | H8: =IF(OR('Historical FS'!G26<=0,'Historical FS'!H26<=0),"N/M",'Historical FS'!H26/'Historical FS'!G26 -1) -> 2.8855055 | I8: =IF(OR('Historical FS'!H26<=0,'Historical FS'!I26<=0),"N/M",'Historical FS'!I26/'Historical FS'!H26 -1) -> 1.7836991 | J8: =IFERROR('Historical FS'!J26/'Historical FS'!I26 -1,0) -> -0.3286036 | K8: =IFERROR('Historical FS'!K26/'Historical FS'!J26 -1,0) -> -0.40586213 | L8: =IFERROR('Historical FS'!L26/'Historical FS'!K26 -1,0) -> 0.19599125 | N8: =IFERROR('The 3-Statement Projection'!D19/'The 3-Statement Projection'!C19-1,0) -> 0.97114356 | O8: =IFERROR('The 3-Statement Projection'!E19/'The 3-Statement Projection'!D19-1,0) -> -0.062087675 | P8: =IFERROR('The 3-Statement Projection'!F19/'The 3-Statement Projection'!E19-1,0) -> 0.010009334 | Q8: =IFERROR('The 3-Statement Projection'!G19/'The 3-Statement Projection'!F19-1,0) -> 0.0098109552 | R8: =IFERROR('The 3-Statement Projection'!H19/'The 3-Statement Projection'!G19-1,0) -> -0.004127747 | S8: =IFERROR('The 3-Statement Projection'!I19/'The 3-Statement Projection'!H19-1,0) -> -0.0042484773 | T8: =IFERROR('The 3-Statement Projection'!J19/'The 3-Statement Projection'!I19-1,0) -> -0.0043732689 | U8: =IFERROR('The 3-Statement Projection'!K19/'The 3-Statement Projection'!J19-1,0) -> -0.0045022904 | V8: EBIT Growth = (EBIT CY / EBIT PY) − 1 | W8: EBIT growth mirrors EBITDA volatility but with sharper movements, highlighting the additional impact of depreciation and fixed costs. Large swings (e.g., +288% in FY21, -71% in FY20) suggest high operating leverage, making profitability highly sensitive to revenue changes.
B9: Net Profit Growth | C9: - | D9: =IF(OR('Historical FS'!C42<=0,'Historical FS'!D42<=0),"N/M",'Historical FS'!D42/'Historical FS'!C42 -1) -> N/M | E9: =IF(OR('Historical FS'!D42<=0,'Historical FS'!E42<=0),"N/M",'Historical FS'!E42/'Historical FS'!D42 -1) -> 1.3653289 | F9: =IF(OR('Historical FS'!E42<=0,'Historical FS'!F42<=0),"N/M",'Historical FS'!F42/'Historical FS'!E42 -1) -> -0.29840826 | G9: =IF(OR('Historical FS'!F42<=0,'Historical FS'!G42<=0),"N/M",'Historical FS'!G42/'Historical FS'!F42 -1) -> N/M | H9: =IF(OR('Historical FS'!G42<=0,'Historical FS'!H42<=0),"N/M",'Historical FS'!H42/'Historical FS'!G42 -1) -> N/M | I9: =IF(OR('Historical FS'!H42<=0,'Historical FS'!I42<=0),"N/M",'Historical FS'!I42/'Historical FS'!H42 -1) -> 3.1273764 | J9: =IFERROR('Historical FS'!J42/'Historical FS'!I42 -1,0) -> -0.30915791 | K9: =IFERROR('Historical FS'!K42/'Historical FS'!J42 -1,0) -> -0.39677537 | L9: =IFERROR('Historical FS'!L42/'Historical FS'!K42 -1,0) -> 0.15152733 | N9: =IFERROR('The 3-Statement Projection'!D27/'The 3-Statement Projection'!C27-1,0) -> 0.97042475 | O9: =IFERROR('The 3-Statement Projection'!E27/'The 3-Statement Projection'!D27-1,0) -> -0.11529376 | P9: =IFERROR('The 3-Statement Projection'!F27/'The 3-Statement Projection'!E27-1,0) -> 0.05290939 | Q9: =IFERROR('The 3-Statement Projection'!G27/'The 3-Statement Projection'!F27-1,0) -> 0.026028736 | R9: =IFERROR('The 3-Statement Projection'!H27/'The 3-Statement Projection'!G27-1,0) -> 0.0095162408 | S9: =IFERROR('The 3-Statement Projection'!I27/'The 3-Statement Projection'!H27-1,0) -> 0.009266916 | T9: =IFERROR('The 3-Statement Projection'!J27/'The 3-Statement Projection'!I27-1,0) -> 0.0090668112 | U9: =IFERROR('The 3-Statement Projection'!K27/'The 3-Statement Projection'!J27-1,0) -> 0.0088685092 | V9: Net Profit Growth = (PAT CY / PAT PY) − 1 | W9: Net profit grew +15% in FY25 to ₹114.6 Cr, trailing EBITDA/EBIT growth due to higher interest expense (re-levering for Battery-2). Still meaningfully below FY22 supernormal peak (₹239 Cr). Earliest years (FY17-FY21) show N/M due to negative-base distortions.
B11: 2. Profitability Ratios
B12: Gross Margin | C12: =IFERROR('Historical FS'!C12,0) -> 0.058142131 | D12: =IFERROR('Historical FS'!D12,0) -> 0.21470028 | E12: =IFERROR('Historical FS'!E12,0) -> 0.23148982 | F12: =IFERROR('Historical FS'!F12,0) -> 0.1948203 | G12: =IFERROR('Historical FS'!G12,0) -> 0.12629147 | H12: =IFERROR('Historical FS'!H12,0) -> 0.25356946 | I12: =IFERROR('Historical FS'!I12,0) -> 0.35027293 | J12: =IFERROR('Historical FS'!J12,0) -> 0.16172472 | ... L12: =IFERROR('Historical FS'!L12,0) -> 0.15809077 | N12: =IFERROR('The 3-Statement Projection'!D10/'The 3-Statement Projection'!D6,0) -> 0.22917245 | O12: =IFERROR('The 3-Statement Projection'!E10/'The 3-Statement Projection'!E6,0) -> 0.21076871 | P12: =IFERROR('The 3-Statement Projection'!F10/'The 3-Statement Projection'!F6,0) -> 0.21276871 | Q12: =IFERROR('The 3-Statement Projection'!G10/'The 3-Statement Projection'!G6,0) -> 0.21476871 | R12: =IFERROR('The 3-Statement Projection'!H10/'The 3-Statement Projection'!H6,0) -> 0.21476871 | S12: =IFERROR('The 3-Statement Projection'!I10/'The 3-Statement Projection'!I6,0) -> 0.21476871 | T12: =IFERROR('The 3-Statement Projection'!J10/'The 3-Statement Projection'!J6,0) -> 0.21476871 | U12: =IFERROR('The 3-Statement Projection'!K10/'The 3-Statement Projection'!K6,0) -> 0.21476871 | V12: Gross Margin = Gross Profit / Net Sales | W12: Gross margin recovered to 15.8% in FY25 (from 15.0% FY24), a modest improvement. Still far below the FY22 peak of 35% driven by favourable coke spreads. The business remains a commodity margin play — gross margin is highly sensitive to coke price cycles and imported coal costs.
B13: EBITDA Margin | C13: =IFERROR('Historical FS'!C21,0) -> -0.014402948 | D13: =IFERROR('Historical FS'!D21,0) -> 0.16700434 | E13: =IFERROR('Historical FS'!E21,0) -> 0.18352549 | F13: =IFERROR('Historical FS'!F21,0) -> 0.14014214 | G13: =IFERROR('Historical FS'!G21,0) -> 0.066690297 | H13: =IFERROR('Historical FS'!H21,0) -> 0.1933274 | I13: =IFERROR('Historical FS'!I21,0) -> 0.30305299 | J13: =IFERROR('Historical FS'!J21,0) -> 0.13041231 | ... L13: =IFERROR('Historical FS'!L21,0) -> 0.10711099 | N13: =IFERROR('The 3-Statement Projection'!D16,0) -> 0.18247245 | O13: =IFERROR('The 3-Statement Projection'!E16,0) -> 0.16406871 | P13: =IFERROR('The 3-Statement Projection'!F16,0) -> 0.16606871 | Q13: =IFERROR('The 3-Statement Projection'!G16,0) -> 0.16806871 | R13: =IFERROR('The 3-Statement Projection'!H16,0) -> 0.16806871 | S13: =IFERROR('The 3-Statement Projection'!I16,0) -> 0.16806871 | T13: =IFERROR('The 3-Statement Projection'!J16,0) -> 0.16806871 | U13: =IFERROR('The 3-Statement Projection'!K16,0) -> 0.16806871 | V13: EBITDA Margin = EBITDA / Net Sales | W13: EBITDA margin ticked up to 10.7% in FY25 (from 10.4% FY24), still meaningfully below the FY22 peak of 30.3%. Operating leverage is intact but coke spreads remain mid-cycle. Management forecasts 16.8% by FY29E on volume ramp and mix improvement.
B14: EBIT Margin | C14: =IFERROR('Historical FS'!C27,0) -> -0.095656786 | D14: =IFERROR('Historical FS'!D27,0) -> 0.12230939 | E14: =IFERROR('Historical FS'!E27,0) -> 0.15279905 | F14: =IFERROR('Historical FS'!F27,0) -> 0.12175602 | G14: =IFERROR('Historical FS'!G27,0) -> 0.043112389 | H14: =IFERROR('Historical FS'!H27,0) -> 0.1671426 | I14: =IFERROR('Historical FS'!I27,0) -> 0.28597652 | J14: =IFERROR('Historical FS'!J27,0) -> 0.1196504 | ... L14: =IFERROR('Historical FS'!L27,0) -> 0.090555915 | N14: =IFERROR('The 3-Statement Projection'!D19/'The 3-Statement Projection'!D6,0) -> 0.1605056 | O14: =IFERROR('The 3-Statement Projection'!E19/'The 3-Statement Projection'!E6,0) -> 0.14268959 | P14: =IFERROR('The 3-Statement Projection'!F19/'The 3-Statement Projection'!F6,0) -> 0.14411782 | Q14: =IFERROR('The 3-Statement Projection'!G19/'The 3-Statement Projection'!G6,0) -> 0.14553175 | R14: =IFERROR('The 3-Statement Projection'!H19/'The 3-Statement Projection'!H6,0) -> 0.14493103 | S14: =IFERROR('The 3-Statement Projection'!I19/'The 3-Statement Projection'!I6,0) -> 0.14431529 | T14: =IFERROR('The 3-Statement Projection'!J19/'The 3-Statement Projection'!J6,0) -> 0.14368416 | U14: =IFERROR('The 3-Statement Projection'!K19/'The 3-Statement Projection'!K6,0) -> 0.14303726 | V14: EBIT Margin = EBIT / Net Sales | W14: EBIT margin at 9.1% in FY25 (up modestly from 9.0% FY24) remains below the 9-year median and far from the FY22 peak of 28.6%. Below-mid-cycle profitability; depreciation intensity is rising with Battery-2 capitalised, adding a structural drag that volume growth must offset.
